Workbook

Sheet How to Use
A1: How to use this dashboard
A2: 1. Add a transaction: Open the relevant 'Txn-…' sheet and type a new row anywhere below the existing data — the Excel table extends automatically and the dashboard recalculates.
A3: 2. Delete a transaction: Right-click a row inside the Txn-* table → Delete → Table Rows.
A4: 3. Refresh NAVs: Edit values on the 'NAV Reference' sheet. Current Value, Gain, and % Return all update.
A5: 4. Merge two scheme variants under one MF: Open 'Scheme Map' and edit the Display Scheme for a raw scheme to match another. Also update the 'Display Scheme' column in the affected Txn-* sheets so the dashboard groups them together.
A6: 5. Status column: 'Redeemed' = net units near zero. 'In Profit' / 'In Loss' = current value vs. invested.
A7: 6. Net Invested = Buy amount − Sell amount per scheme. Avg Cost NAV = Net Invested / Net Units.
A8: 7. NAV Source 'MoneyControl' = pulled from the latest MC export. 'Last txn NAV' = no MC entry; we used the most recent transaction NAV (likely stale for fully-redeemed schemes).
A9: 8. To re-build from raw platform/MC files, run python build_dashboard.py followed by python write_dashboard.py.

Sheet Dashboard
A1: Mutual Funds Portfolio Dashboard
A2: ="As of "&TEXT(MAX(NAVAll!F:F),"d mmm yyyy")&" • All KPIs and tables update automatically when transactions are added/deleted." -> As of 28 Jun 2026 • All KPIs and tables update automatically when transactions are added/deleted.
D3: 6857701
A4: Snapshot
A5: Net Invested | C5: Current Value | E5: Net Gain / Loss | G5: Total Return % | J5: Active Schemes | K5: XIRR
A6: =SUM(MFwise[Net Invested]) -> 4409837.1 | C6: =SUM(MFwise[Current Value]) -> 6847516.3 | E6: =SUM(MFwise[Gain/Loss]) -> 2632962.4 | G6: =IFERROR(SUM(MFwise[Gain/Loss])/SUM(MFwise[Net Invested]),0) -> 0.5970657 | J6: =SUMPRODUCT(--(MFwise[Net Units]>0.01)) -> 23 | K6: =$I$87 -> 0.12432699
D7: 1599887
D8: 1669183 | E8: =D8+D7+C6 -> 10116586
A9: MF-Wise Portfolio
A10: Display Scheme | B10: Net Units | C10: Net Invested | D10: Avg Cost NAV | E10: Latest NAV | F10: Current Value | G10: Gain/Loss | H10: P&L Type | I10: % Gain | J10: Status | K10: XIRR
A11: Aditya Birla Sun Life Banking And Financial Services Fund Growth | B11: =SUMIFS(tICICIAshu[Signed Unit],tICICIAshu[Display Scheme],$A11)+SUMIFS(tManiqAshu[Signed Unit],tManiqAshu[Display Scheme],$A11)+SUMIFS(tManiqHars[Signed Unit],tManiqHars[Display Scheme],$A11)+SUMIFS(tZerodhAshu[Signed Unit],tZerodhAshu[Display Scheme],$A11)+SUMIFS(tZerodhHars[Signed Unit],tZerodhHars[Display Scheme],$A11) -> 3475.826 | C11: =IF(B11<0.01,0,SUMIFS(tICICIAshu[Signed Amount],tICICIAshu[Display Scheme],$A11)+SUMIFS(tManiqAshu[Signed Amount],tManiqAshu[Display Scheme],$A11)+SUMIFS(tManiqHars[Signed Amount],tManiqHars[Display Scheme],$A11)+SUMIFS(tZerodhAshu[Signed Amount],tZerodhAshu[Display Scheme],$A11)+SUMIFS(tZerodhHars[Signed Amount],tZerodhHars[Display Scheme],$A11)) -> 159992.32 | D11: =IFERROR(IF(B11<0.01,0,C11/B11),0) -> 46.030014 | E11: =IFERROR(VLOOKUP($A11,tNAV[[Display Scheme]:[Latest NAV]],3,FALSE()),0) -> 63.59 | F11: =B11*E11 -> 221027.78 | G11: =F11-(SUMIFS(tICICIAshu[Signed Amount],tICICIAshu[Display Scheme],$A11)+SUMIFS(tManiqAshu[Signed Amount],tManiqAshu[Display Scheme],$A11)+SUMIFS(tManiqHars[Signed Amount],tManiqHars[Display Scheme],$A11)+SUMIFS(tZerodhAshu[Signed Amount],tZerodhAshu[Display Scheme],$A11)+SUMIFS(tZerodhHars[Signed Amount],tZerodhHars[Display Scheme],$A11)) -> 61035.455 | H11: =IF(B11<0.01,"Realized","Unrealized") -> Unrealized | I11: =IFERROR(G11/ABS(SUMIFS(tICICIAshu[Signed Amount],tICICIAshu[Display Scheme],$A11)+SUMIFS(tManiqAshu[Signed Amount],tManiqAshu[Display Scheme],$A11)+SUMIFS(tManiqHars[Signed Amount],tManiqHars[Display Scheme],$A11)+SUMIFS(tZerodhAshu[Signed Amount],tZerodhAshu[Display Scheme],$A11)+SUMIFS(tZerodhHars[Signed Amount],tZerodhHars[Display Scheme],$A11)),0) -> 0.38148991 | J11: =IF(B11<0.01,"Redeemed",IF(C11<=0,"Active",IF(G11>=0,"In Profit","In Loss"))) -> In Profit | K11: {=IFERROR(IF(F11<=0,"",XIRR(_xlfn.VSTACK(_xlfn._xlws.FILTER(-tAllCF[Signed Amount],tAllCF[Display Scheme]=$A11),F11),_xlfn.VSTACK(_xlfn._xlws.FILTER(tAllCF[Date],tAllCF[Display Scheme]=$A11),TODAY()))),"")} -> 0.13688293
A12: Aditya Birla Sun Life Value Fund Growth | B12: =SUMIFS(tICICIAshu[Signed Unit],tICICIAshu[Display Scheme],$A12)+SUMIFS(tManiqAshu[Signed Unit],tManiqAshu[Display Scheme],$A12)+SUMIFS(tManiqHars[Signed Unit],tManiqHars[Display Scheme],$A12)+SUMIFS(tZerodhAshu[Signed Unit],tZerodhAshu[Display Scheme],$A12)+SUMIFS(tZerodhHars[Signed Unit],tZerodhHars[Display Scheme],$A12) -> 912.432 | C12: =IF(B12<0.01,0,SUMIFS(tICICIAshu[Signed Amount],tICICIAshu[Display Scheme],$A12)+SUMIFS(tManiqAshu[Signed Amount],tManiqAshu[Display Scheme],$A12)+SUMIFS(tManiqHars[Signed Amount],tManiqHars[Display Scheme],$A12)+SUMIFS(tZerodhAshu[Signed Amount],tZerodhAshu[Display Scheme],$A12)+SUMIFS(tZerodhHars[Signed Amount],tZerodhHars[Display Scheme],$A12)) -> 64996.75 | D12: =IFERROR(IF(B12<0.01,0,C12/B12),0) -> 71.234624 | E12: =IFERROR(VLOOKUP($A12,tNAV[[Display Scheme]:[Latest NAV]],3,FALSE()),0) -> 133.0035 | F12: =B12*E12 -> 121356.65 | G12: =F12-(SUMIFS(tICICIAshu[Signed Amount],tICICIAshu[Display Scheme],$A12)+SUMIFS(tManiqAshu[Signed Amount],tManiqAshu[Display Scheme],$A12)+SUMIFS(tManiqHars[Signed Amount],tManiqHars[Display Scheme],$A12)+SUMIFS(tZerodhAshu[Signed Amount],tZerodhAshu[Display Scheme],$A12)+SUMIFS(tZerodhHars[Signed Amount],tZerodhHars[Display Scheme],$A12)) -> 56359.9 | H12: =IF(B12<0.01,"Realized","Unrealized") -> Unrealized | I12: =IFERROR(G12/ABS(SUMIFS(tICICIAshu[Signed Amount],tICICIAshu[Display Scheme],$A12)+SUMIFS(tManiqAshu[Signed Amount],tManiqAshu[Display Scheme],$A12)+SUMIFS(tManiqHars[Signed Amount],tManiqHars[Display Scheme],$A12)+SUMIFS(tZerodhAshu[Signed Amount],tZerodhAshu[Display Scheme],$A12)+SUMIFS(tZerodhHars[Signed Amount],tZerodhHars[Display Scheme],$A12)),0) -> 0.86711873 | J12: =IF(B12<0.01,"Redeemed",IF(C12<=0,"Active",IF(G12>=0,"In Profit","In Loss"))) -> In Profit | K12: {=IFERROR(IF(F12<=0,"",XIRR(_xlfn.VSTACK(_xlfn._xlws.FILTER(-tAllCF[Signed Amount],tAllCF[Display Scheme]=$A12),F12),_xlfn.VSTACK(_xlfn._xlws.FILTER(tAllCF[Date],tAllCF[Display Scheme]=$A12),TODAY()))),"")} -> 0.14765902
A13: Canara Robeco Large And Mid Cap Fund Growth | B13: =SUMIFS(tICICIAshu[Signed Unit],tICICIAshu[Display Scheme],$A13)+SUMIFS(tManiqAshu[Signed Unit],tManiqAshu[Display Scheme],$A13)+SUMIFS(tManiqHars[Signed Unit],tManiqHars[Display Scheme],$A13)+SUMIFS(tZerodhAshu[Signed Unit],tZerodhAshu[Display Scheme],$A13)+SUMIFS(tZerodhHars[Signed Unit],tZerodhHars[Display Scheme],$A13) -> 5337.045 | C13: =IF(B13<0.01,0,SUMIFS(tICICIAshu[Signed Amount],tICICIAshu[Display Scheme],$A13)+SUMIFS(tManiqAshu[Signed Amount],tManiqAshu[Display Scheme],$A13)+SUMIFS(tManiqHars[Signed Amount],tManiqHars[Display Scheme],$A13)+SUMIFS(tZerodhAshu[Signed Amount],tZerodhAshu[Display Scheme],$A13)+SUMIFS(tZerodhHars[Signed Amount],tZerodhHars[Display Scheme],$A13)) -> 792485.68 | D13: =IFERROR(IF(B13<0.01,0,C13/B13),0) -> 148.48773 | E13: =IFERROR(VLOOKUP($A13,tNAV[[Display Scheme]:[Latest NAV]],3,FALSE()),0) -> 250.89 | F13: =B13*E13 -> 1339011.2 | G13: =F13-(SUMIFS(tICICIAshu[Signed Amount],tICICIAshu[Display Scheme],$A13)+SUMIFS(tManiqAshu[Signed Amount],tManiqAshu[Display Scheme],$A13)+SUMIFS(tManiqHars[Signed Amount],tManiqHars[Display Scheme],$A13)+SUMIFS(tZerodhAshu[Signed Amount],tZerodhAshu[Display Scheme],$A13)+SUMIFS(tZerodhHars[Signed Amount],tZerodhHars[Display Scheme],$A13)) -> 546525.54 | H13: =IF(B13<0.01,"Realized","Unrealized") -> Unrealized | I13: =IFERROR(G13/ABS(SUMIFS(tICICIAshu[Signed Amount],tICICIAshu[Display Scheme],$A13)+SUMIFS(tManiqAshu[Signed Amount],tManiqAshu[Display Scheme],$A13)+SUMIFS(tManiqHars[Signed Amount],tManiqHars[Display Scheme],$A13)+SUMIFS(tZerodhAshu[Signed Amount],tZerodhAshu[Display Scheme],$A13)+SUMIFS(tZerodhHars[Signed Amount],tZerodhHars[Display Scheme],$A13)),0) -> 0.68963459 | J13: =IF(B13<0.01,"Redeemed",IF(C13<=0,"Active",IF(G13>=0,"In Profit","In Loss"))) -> In Profit | K13: {=IFERROR(IF(F13<=0,"",XIRR(_xlfn.VSTACK(_xlfn._xlws.FILTER(-tAllCF[Signed Amount],tAllCF[Display Scheme]=$A13),F13),_xlfn.VSTACK(_xlfn._xlws.FILTER(tAllCF[Date],tAllCF[Display Scheme]=$A13),TODAY()))),"")} -> 0.12094044
A14: Canara Robeco Large Cap Fund Regulargrowth | B14: =SUMIFS(tICICIAshu[Signed Unit],tICICIAshu[Display Scheme],$A14)+SUMIFS(tManiqAshu[Signed Unit],tManiqAshu[Display Scheme],$A14)+SUMIFS(tManiqHars[Signed Unit],tManiqHars[Display Scheme],$A14)+SUMIFS(tZerodhAshu[Signed Unit],tZerodhAshu[Display Scheme],$A14)+SUMIFS(tZerodhHars[Signed Unit],tZerodhHars[Display Scheme],$A14) -> 1410.698 | C14: =IF(B14<0.01,0,SUMIFS(tICICIAshu[Signed Amount],tICICIAshu[Display Scheme],$A14)+SUMIFS(tManiqAshu[Signed Amount],tManiqAshu[Display Scheme],$A14)+SUMIFS(tManiqHars[Signed Amount],tManiqHars[Display Scheme],$A14)+SUMIFS(tZerodhAshu[Signed Amount],tZerodhAshu[Display Scheme],$A14)+SUMIFS(tZerodhHars[Signed Amount],tZerodhHars[Display Scheme],$A14)) -> 60000 | D14: =IFERROR(IF(B14<0.01,0,C14/B14),0) -> 42.532137 | E14: =IFERROR(VLOOKUP($A14,tNAV[[Display Scheme]:[Latest NAV]],3,FALSE()),0) -> 61.15 | F14: =B14*E14 -> 86264.183 | G14: =F14-(SUMIFS(tICICIAshu[Signed Amount],tICICIAshu[Display Scheme],$A14)+SUMIFS(tManiqAshu[Signed Amount],tManiqAshu[Display Scheme],$A14)+SUMIFS(tManiqHars[Signed Amount],tManiqHars[Display Scheme],$A14)+SUMIFS(tZerodhAshu[Signed Amount],tZerodhAshu[Display Scheme],$A14)+SUMIFS(tZerodhHars[Signed Amount],tZerodhHars[Display Scheme],$A14)) -> 26264.183 | H14: =IF(B14<0.01,"Realized","Unrealized") -> Unrealized | I14: =IFERROR(G14/ABS(SUMIFS(tICICIAshu[Signed Amount],tICICIAshu[Display Scheme],$A14)+SUMIFS(tManiqAshu[Signed Amount],tManiqAshu[Display Scheme],$A14)+SUMIFS(tManiqHars[Signed Amount],tManiqHars[Display Scheme],$A14)+SUMIFS(tZerodhAshu[Signed Amount],tZerodhAshu[Display Scheme],$A14)+SUMIFS(tZerodhHars[Signed Amount],tZerodhHars[Display Scheme],$A14)),0) -> 0.43773638 | J14: =IF(B14<0.01,"Redeemed",IF(C14<=0,"Active",IF(G14>=0,"In Profit","In Loss"))) -> In Profit | K14: {=IFERROR(IF(F14<=0,"",XIRR(_xlfn.VSTACK(_xlfn._xlws.FILTER(-tAllCF[Signed Amount],tAllCF[Display Scheme]=$A14),F14),_xlfn.VSTACK(_xlfn._xlws.FILTER(tAllCF[Date],tAllCF[Display Scheme]=$A14),TODAY()))),"")} -> 0.079373416
A15: Hdfc Flexicap Fund Direct Growth Option | B15: =SUMIFS(tICICIAshu[Signed Unit],tICICIAshu[Display Scheme],$A15)+SUMIFS(tManiqAshu[Signed Unit],tManiqAshu[Display Scheme],$A15)+SUMIFS(tManiqHars[Signed Unit],tManiqHars[Display Scheme],$A15)+SUMIFS(tZerodhAshu[Signed Unit],tZerodhAshu[Display Scheme],$A15)+SUMIFS(tZerodhHars[Signed Unit],tZerodhHars[Display Scheme],$A15) -> 110.823 | C15: =IF(B15<0.01,0,SUMIFS(tICICIAshu[Signed Amount],tICICIAshu[Display Scheme],$A15)+SUMIFS(tManiqAshu[Signed Amount],tManiqAshu[Display Scheme],$A15)+SUMIFS(tManiqHars[Signed Amount],tManiqHars[Display Scheme],$A15)+SUMIFS(tZerodhAshu[Signed Amount],tZerodhAshu[Display Scheme],$A15)+SUMIFS(tZerodhHars[Signed Amount],tZerodhHars[Display Scheme],$A15)) -> 249989.61 | D15: =IFERROR(IF(B15<0.01,0,C15/B15),0) -> 2255.7557 | E15: =IFERROR(VLOOKUP($A15,tNAV[[Display Scheme]:[Latest NAV]],3,FALSE()),0) -> 2215.087 | F15: =B15*E15 -> 245482.59 | G15: =F15-(SUMIFS(tICICIAshu[Signed Amount],tICICIAshu[Display Scheme],$A15)+SUMIFS(tManiqAshu[Signed Amount],tManiqAshu[Display Scheme],$A15)+SUMIFS(tManiqHars[Signed Amount],tManiqHars[Display Scheme],$A15)+SUMIFS(tZerodhAshu[Signed Amount],tZerodhAshu[Display Scheme],$A15)+SUMIFS(tZerodhHars[Signed Amount],tZerodhHars[Display Scheme],$A15)) -> -4507.0234 | H15: =IF(B15<0.01,"Realized","Unrealized") -> Unrealized | I15: =IFERROR(G15/ABS(SUMIFS(tICICIAshu[Signed Amount],tICICIAshu[Display Scheme],$A15)+SUMIFS(tManiqAshu[Signed Amount],tManiqAshu[Display Scheme],$A15)+SUMIFS(tManiqHars[Signed Amount],tManiqHars[Display Scheme],$A15)+SUMIFS(tZerodhAshu[Signed Amount],tZerodhAshu[Display Scheme],$A15)+SUMIFS(tZerodhHars[Signed Amount],tZerodhHars[Display Scheme],$A15)),0) -> -0.018028843 | J15: =IF(B15<0.01,"Redeemed",IF(C15<=0,"Active",IF(G15>=0,"In Profit","In Loss"))) -> In Loss | K15: {=IFERROR(IF(F15<=0,"",XIRR(_xlfn.VSTACK(_xlfn._xlws.FILTER(-tAllCF[Signed Amount],tAllCF[Display Scheme]=$A15),F15),_xlfn.VSTACK(_xlfn._xlws.FILTER(tAllCF[Date],tAllCF[Display Scheme]=$A15),TODAY()))),"")} -> -0.029031786
A16: Hdfc Gold Etf Fund Of Fund Direct Growth Option | B16: =SUMIFS(tICICIAshu[Signed Unit],tICICIAshu[Display Scheme],$A16)+SUMIFS(tManiqAshu[Signed Unit],tManiqAshu[Display Scheme],$A16)+SUMIFS(tManiqHars[Signed Unit],tManiqHars[Display Scheme],$A16)+SUMIFS(tZerodhAshu[Signed Unit],tZerodhAshu[Display Scheme],$A16)+SUMIFS(tZerodhHars[Signed Unit],tZerodhHars[Display Scheme],$A16) -> 4570.112 | C16: =IF(B16<0.01,0,SUMIFS(tICICIAshu[Signed Amount],tICICIAshu[Display Scheme],$A16)+SUMIFS(tManiqAshu[Signed Amount],tManiqAshu[Display Scheme],$A16)+SUMIFS(tManiqHars[Signed Amount],tManiqHars[Display Scheme],$A16)+SUMIFS(tZerodhAshu[Signed Amount],tZerodhAshu[Display Scheme],$A16)+SUMIFS(tZerodhHars[Signed Amount],tZerodhHars[Display Scheme],$A16)) -> 199990.01 | D16: =IFERROR(IF(B16<0.01,0,C16/B16),0) -> 43.760418 | E16: =IFERROR(VLOOKUP($A16,tNAV[[Display Scheme]:[Latest NAV]],3,FALSE()),0) -> 43.279 | F16: =B16*E16 -> 197789.88 | G16: =F16-(SUMIFS(tICICIAshu[Signed Amount],tICICIAshu[Display Scheme],$A16)+SUMIFS(tManiqAshu[Signed Amount],tManiqAshu[Display Scheme],$A16)+SUMIFS(tManiqHars[Signed Amount],tManiqHars[Display Scheme],$A16)+SUMIFS(tZerodhAshu[Signed Amount],tZerodhAshu[Display Scheme],$A16)+SUMIFS(tZerodhHars[Signed Amount],tZerodhHars[Display Scheme],$A16)) -> -2200.1328 | H16: =IF(B16<0.01,"Realized","Unrealized") -> Unrealized | I16: =IFERROR(G16/ABS(SUMIFS(tICICIAshu[Signed Amount],tICICIAshu[Display Scheme],$A16)+SUMIFS(tManiqAshu[Signed Amount],tManiqAshu[Display Scheme],$A16)+SUMIFS(tManiqHars[Signed Amount],tManiqHars[Display Scheme],$A16)+SUMIFS(tZerodhAshu[Signed Amount],tZerodhAshu[Display Scheme],$A16)+SUMIFS(tZerodhHars[Signed Amount],tZerodhHars[Display Scheme],$A16)),0) -> -0.011001213 | J16: =IF(B16<0.01,"Redeemed",IF(C16<=0,"Active",IF(G16>=0,"In Profit","In Loss"))) -> In Loss | K16: {=IFERROR(IF(F16<=0,"",XIRR(_xlfn.VSTACK(_xlfn._xlws.FILTER(-tAllCF[Signed Amount],tAllCF[Display Scheme]=$A16),F16),_xlfn.VSTACK(_xlfn._xlws.FILTER(tAllCF[Date],tAllCF[Display Scheme]=$A16),TODAY()))),"")} -> -0.021680173
A17: Hdfc Mid Cap Fund - Growth Option | B17: =SUMIFS(tICICIAshu[Signed Unit],tICICIAshu[Display Scheme],$A17)+SUMIFS(tManiqAshu[Signed Unit],tManiqAshu[Display Scheme],$A17)+SUMIFS(tManiqHars[Signed Unit],tManiqHars[Display Scheme],$A17)+SUMIFS(tZerodhAshu[Signed Unit],tZerodhAshu[Display Scheme],$A17)+SUMIFS(tZerodhHars[Signed Unit],tZerodhHars[Display Scheme],$A17) -> 2069.522 | C17: =IF(B17<0.01,0,SUMIFS(tICICIAshu[Signed Amount],tICICIAshu[Display Scheme],$A17)+SUMIFS(tManiqAshu[Signed Amount],tManiqAshu[Display Scheme],$A17)+SUMIFS(tManiqHars[Signed Amount],tManiqHars[Display Scheme],$A17)+SUMIFS(tZerodhAshu[Signed Amount],tZerodhAshu[Display Scheme],$A17)+SUMIFS(tZerodhHars[Signed Amount],tZerodhHars[Display Scheme],$A17)) -> 90000 | D17: =IFERROR(IF(B17<0.01,0,C17/B17),0) -> 43.488303 | E17: =IFERROR(VLOOKUP($A17,tNAV[[Display Scheme]:[Latest NAV]],3,FALSE()),0) -> 204.864 | F17: =B17*E17 -> 423970.56 | G17: =F17-(SUMIFS(tICICIAshu[Signed Amount],tICICIAshu[Display Scheme],$A17)+SUMIFS(tManiqAshu[Signed Amount],tManiqAshu[Display Scheme],$A17)+SUMIFS(tManiqHars[Signed Amount],tManiqHars[Display Scheme],$A17)+SUMIFS(tZerodhAshu[Signed Amount],tZerodhAshu[Display Scheme],$A17)+SUMIFS(tZerodhHars[Signed Amount],tZerodhHars[Display Scheme],$A17)) -> 333970.56 | H17: =IF(B17<0.01,"Realized","Unrealized") -> Unrealized | I17: =IFERROR(G17/ABS(SUMIFS(tICICIAshu[Signed Amount],tICICIAshu[Display Scheme],$A17)+SUMIFS(tManiqAshu[Signed Amount],tManiqAshu[Display Scheme],$A17)+SUMIFS(tManiqHars[Signed Amount],tManiqHars[Display Scheme],$A17)+SUMIFS(tZerodhAshu[Signed Amount],tZerodhAshu[Display Scheme],$A17)+SUMIFS(tZerodhHars[Signed Amount],tZerodhHars[Display Scheme],$A17)),0) -> 3.7107839 | J17: =IF(B17<0.01,"Redeemed",IF(C17<=0,"Active",IF(G17>=0,"In Profit","In Loss"))) -> In Profit | K17: {=IFERROR(IF(F17<=0,"",XIRR(_xlfn.VSTACK(_xlfn._xlws.FILTER(-tAllCF[Signed Amount],tAllCF[Display Scheme]=$A17),F17),_xlfn.VSTACK(_xlfn._xlws.FILTER(tAllCF[Date],tAllCF[Display Scheme]=$A17),TODAY()))),"")} -> 0.16650087
A18: Hdfc Silver Etf Fund Of Fund Direct Growth | B18: =SUMIFS(tICICIAshu[Signed Unit],tICICIAshu[Display Scheme],$A18)+SUMIFS(tManiqAshu[Signed Unit],tManiqAshu[Display Scheme],$A18)+SUMIFS(tManiqHars[Signed Unit],tManiqHars[Display Scheme],$A18)+SUMIFS(tZerodhAshu[Signed Unit],tZerodhAshu[Display Scheme],$A18)+SUMIFS(tZerodhHars[Signed Unit],tZerodhHars[Display Scheme],$A18) -> 2613.312 | C18: =IF(B18<0.01,0,SUMIFS(tICICIAshu[Signed Amount],tICICIAshu[Display Scheme],$A18)+SUMIFS(tManiqAshu[Signed Amount],tManiqAshu[Display Scheme],$A18)+SUMIFS(tManiqHars[Signed Amount],tManiqHars[Display Scheme],$A18)+SUMIFS(tZerodhAshu[Signed Amount],tZerodhAshu[Display Scheme],$A18)+SUMIFS(tZerodhHars[Signed Amount],tZerodhHars[Display Scheme],$A18)) -> 129993.47 | D18: =IFERROR(IF(B18<0.01,0,C18/B18),0) -> 49.742805 | E18: =IFERROR(VLOOKUP($A18,tNAV[[Display Scheme]:[Latest NAV]],3,FALSE()),0) -> 35.6537 | F18: =B18*E18 -> 93174.242 | G18: =F18-(SUMIFS(tICICIAshu[Signed Amount],tICICIAshu[Display Scheme],$A18)+SUMIFS(tManiqAshu[Signed Amount],tManiqAshu[Display Scheme],$A18)+SUMIFS(tManiqHars[Signed Amount],tManiqHars[Display Scheme],$A18)+SUMIFS(tZerodhAshu[Signed Amount],tZerodhAshu[Display Scheme],$A18)+SUMIFS(tZerodhHars[Signed Amount],tZerodhHars[Display Scheme],$A18)) -> -36819.228 | H18: =IF(B18<0.01,"Realized","Unrealized") -> Unrealized | I18: =IFERROR(G18/ABS(SUMIFS(tICICIAshu[Signed Amount],tICICIAshu[Display Scheme],$A18)+SUMIFS(tManiqAshu[Signed Amount],tManiqAshu[Display Scheme],$A18)+SUMIFS(tManiqHars[Signed Amount],tManiqHars[Display Scheme],$A18)+SUMIFS(tZerodhAshu[Signed Amount],tZerodhAshu[Display Scheme],$A18)+SUMIFS(tZerodhHars[Signed Amount],tZerodhHars[Display Scheme],$A18)),0) -> -0.28323906 | J18: =IF(B18<0.01,"Redeemed",IF(C18<=0,"Active",IF(G18>=0,"In Profit","In Loss"))) -> In Loss | K18: {=IFERROR(IF(F18<=0,"",XIRR(_xlfn.VSTACK(_xlfn._xlws.FILTER(-tAllCF[Signed Amount],tAllCF[Display Scheme]=$A18),F18),_xlfn.VSTACK(_xlfn._xlws.FILTER(tAllCF[Date],tAllCF[Display Scheme]=$A18),TODAY()))),"")} -> -0.54444951
A19: Icici Prudential Balanced Advantage Fund Direct Growth | B19: =SUMIFS(tICICIAshu[Signed Unit],tICICIAshu[Display Scheme],$A19)+SUMIFS(tManiqAshu[Signed Unit],tManiqAshu[Display Scheme],$A19)+SUMIFS(tManiqHars[Signed Unit],tManiqHars[Display Scheme],$A19)+SUMIFS(tZerodhAshu[Signed Unit],tZerodhAshu[Display Scheme],$A19)+SUMIFS(tZerodhHars[Signed Unit],tZerodhHars[Display Scheme],$A19) -> 295.359 | C19: =IF(B19<0.01,0,SUMIFS(tICICIAshu[Signed Amount],tICICIAshu[Display Scheme],$A19)+SUMIFS(tManiqAshu[Signed Amount],tManiqAshu[Display Scheme],$A19)+SUMIFS(tManiqHars[Signed Amount],tManiqHars[Display Scheme],$A19)+SUMIFS(tZerodhAshu[Signed Amount],tZerodhAshu[Display Scheme],$A19)+SUMIFS(tZerodhHars[Signed Amount],tZerodhHars[Display Scheme],$A19)) -> 24998.93 | D19: =IFERROR(IF(B19<0.01,0,C19/B19),0) -> 84.639134 | E19: =IFERROR(VLOOKUP($A19,tNAV[[Display Scheme]:[Latest NAV]],3,FALSE()),0) -> 86.86 | F19: =B19*E19 -> 25654.883 | G19: =F19-(SUMIFS(tICICIAshu[Signed Amount],tICICIAshu[Display Scheme],$A19)+SUMIFS(tManiqAshu[Signed Amount],tManiqAshu[Display Scheme],$A19)+SUMIFS(tManiqHars[Signed Amount],tManiqHars[Display Scheme],$A19)+SUMIFS(tZerodhAshu[Signed Amount],tZerodhAshu[Display Scheme],$A19)+SUMIFS(tZerodhHars[Signed Amount],tZerodhHars[Display Scheme],$A19)) -> 655.95274 | H19: =IF(B19<0.01,"Realized","Unrealized") -> Unrealized | I19: =IFERROR(G19/ABS(SUMIFS(tICICIAshu[Signed Amount],tICICIAshu[Display Scheme],$A19)+SUMIFS(tManiqAshu[Signed Amount],tManiqAshu[Display Scheme],$A19)+SUMIFS(tManiqHars[Signed Amount],tManiqHars[Display Scheme],$A19)+SUMIFS(tZerodhAshu[Signed Amount],tZerodhAshu[Display Scheme],$A19)+SUMIFS(tZerodhHars[Signed Amount],tZerodhHars[Display Scheme],$A19)),0) -> 0.026239233 | J19: =IF(B19<0.01,"Redeemed",IF(C19<=0,"Active",IF(G19>=0,"In Profit","In Loss"))) -> In Profit | K19: {=IFERROR(IF(F19<=0,"",XIRR(_xlfn.VSTACK(_xlfn._xlws.FILTER(-tAllCF[Signed Amount],tAllCF[Display Scheme]=$A19),F19),_xlfn.VSTACK(_xlfn._xlws.FILTER(tAllCF[Date],tAllCF[Display Scheme]=$A19),TODAY()))),"")} -> 4.0666502
A20: Icici Prudential Focused Equity Fund Growth | B20: =SUMIFS(tICICIAshu[Signed Unit],tICICIAshu[Display Scheme],$A20)+SUMIFS(tManiqAshu[Signed Unit],tManiqAshu[Display Scheme],$A20)+SUMIFS(tManiqHars[Signed Unit],tManiqHars[Display Scheme],$A20)+SUMIFS(tZerodhAshu[Signed Unit],tZerodhAshu[Display Scheme],$A20)+SUMIFS(tZerodhHars[Signed Unit],tZerodhHars[Display Scheme],$A20) -> 2413.867 | C20: =IF(B20<0.01,0,SUMIFS(tICICIAshu[Signed Amount],tICICIAshu[Display Scheme],$A20)+SUMIFS(tManiqAshu[Signed Amount],tManiqAshu[Display Scheme],$A20)+SUMIFS(tManiqHars[Signed Amount],tManiqHars[Display Scheme],$A20)+SUMIFS(tZerodhAshu[Signed Amount],tZerodhAshu[Display Scheme],$A20)+SUMIFS(tZerodhHars[Signed Amount],tZerodhHars[Display Scheme],$A20)) -> 149992.8 | D20: =IFERROR(IF(B20<0.01,0,C20/B20),0) -> 62.137972 | E20: =IFERROR(VLOOKUP($A20,tNAV[[Display Scheme]:[Latest NAV]],3,FALSE()),0) -> 93.49 | F20: =B20*E20 -> 225672.43 | G20: =F20-(SUMIFS(tICICIAshu[Signed Amount],tICICIAshu[Display Scheme],$A20)+SUMIFS(tManiqAshu[Signed Amount],tManiqAshu[Display Scheme],$A20)+SUMIFS(tManiqHars[Signed Amount],tManiqHars[Display Scheme],$A20)+SUMIFS(tZerodhAshu[Signed Amount],tZerodhAshu[Display Scheme],$A20)+SUMIFS(tZerodhHars[Signed Amount],tZerodhHars[Display Scheme],$A20)) -> 75679.626 | H20: =IF(B20<0.01,"Realized","Unrealized") -> Unrealized | I20: =IFERROR(G20/ABS(SUMIFS(tICICIAshu[Signed Amount],tICICIAshu[Display Scheme],$A20)+SUMIFS(tManiqAshu[Signed Amount],tManiqAshu[Display Scheme],$A20)+SUMIFS(tManiqHars[Signed Amount],tManiqHars[Display Scheme],$A20)+SUMIFS(tZerodhAshu[Signed Amount],tZerodhAshu[Display Scheme],$A20)+SUMIFS(tZerodhHars[Signed Amount],tZerodhHars[Display Scheme],$A20)),0) -> 0.50455506 | J20: =IF(B20<0.01,"Redeemed",IF(C20<=0,"Active",IF(G20>=0,"In Profit","In Loss"))) -> In Profit | K20: {=IFERROR(IF(F20<=0,"",XIRR(_xlfn.VSTACK(_xlfn._xlws.FILTER(-tAllCF[Signed Amount],tAllCF[Display Scheme]=$A20),F20),_xlfn.VSTACK(_xlfn._xlws.FILTER(tAllCF[Date],tAllCF[Display Scheme]=$A20),TODAY()))),"")} -> 0.16801437
A21: Icici Prudential Value Fund Growth | B21: =SUMIFS(tICICIAshu[Signed Unit],tICICIAshu[Display Scheme],$A21)+SUMIFS(tManiqAshu[Signed Unit],tManiqAshu[Display Scheme],$A21)+SUMIFS(tManiqHars[Signed Unit],tManiqHars[Display Scheme],$A21)+SUMIFS(tZerodhAshu[Signed Unit],tZerodhAshu[Display Scheme],$A21)+SUMIFS(tZerodhHars[Signed Unit],tZerodhHars[Display Scheme],$A21) -> 269.373 | C21: =IF(B21<0.01,0,SUMIFS(tICICIAshu[Signed Amount],tICICIAshu[Display Scheme],$A21)+SUMIFS(tManiqAshu[Signed Amount],tManiqAshu[Display Scheme],$A21)+SUMIFS(tManiqHars[Signed Amount],tManiqHars[Display Scheme],$A21)+SUMIFS(tZerodhAshu[Signed Amount],tZerodhAshu[Display Scheme],$A21)+SUMIFS(tZerodhHars[Signed Amount],tZerodhHars[Display Scheme],$A21)) -> 64996.75 | D21: =IFERROR(IF(B21<0.01,0,C21/B21),0) -> 241.28903 | E21: =IFERROR(VLOOKUP($A21,tNAV[[Display Scheme]:[Latest NAV]],3,FALSE()),0) -> 462.41 | F21: =B21*E21 -> 124560.77 | G21: =F21-(SUMIFS(tICICIAshu[Signed Amount],tICICIAshu[Display Scheme],$A21)+SUMIFS(tManiqAshu[Signed Amount],tManiqAshu[Display Scheme],$A21)+SUMIFS(tManiqHars[Signed Amount],tManiqHars[Display Scheme],$A21)+SUMIFS(tZerodhAshu[Signed Amount],tZerodhAshu[Display Scheme],$A21)+SUMIFS(tZerodhHars[Signed Amount],tZerodhHars[Display Scheme],$A21)) -> 59564.019 | H21: =IF(B21<0.01,"Realized","Unrealized") -> Unrealized | I21: =IFERROR(G21/ABS(SUMIFS(tICICIAshu[Signed Amount],tICICIAshu[Display Scheme],$A21)+SUMIFS(tManiqAshu[Signed Amount],tManiqAshu[Display Scheme],$A21)+SUMIFS(tManiqHars[Signed Amount],tManiqHars[Display Scheme],$A21)+SUMIFS(tZerodhAshu[Signed Amount],tZerodhAshu[Display Scheme],$A21)+SUMIFS(tZerodhHars[Signed Amount],tZerodhHars[Display Scheme],$A21)),0) -> 0.91641534 | J21: =IF(B21<0.01,"Redeemed",IF(C21<=0,"Active",IF(G21>=0,"In Profit","In Loss"))) -> In Profit | K21: {=IFERROR(IF(F21<=0,"",XIRR(_xlfn.VSTACK(_xlfn._xlws.FILTER(-tAllCF[Signed Amount],tAllCF[Display Scheme]=$A21),F21),_xlfn.VSTACK(_xlfn._xlws.FILTER(tAllCF[Date],tAllCF[Display Scheme]=$A21),TODAY()))),"")} -> 0.15426112
A22: Invesco India Arbitrage Fund - Direct Plan Growth | B22: =SUMIFS(tICICIAshu[Signed Unit],tICICIAshu[Display Scheme],$A22)+SUMIFS(tManiqAshu[Signed Unit],tManiqAshu[Display Scheme],$A22)+SUMIFS(tManiqHars[Signed Unit],tManiqHars[Display Scheme],$A22)+SUMIFS(tZerodhAshu[Signed Unit],tZerodhAshu[Display Scheme],$A22)+SUMIFS(tZerodhHars[Signed Unit],tZerodhHars[Display Scheme],$A22) -> 2787.776 | C22: =IF(B22<0.01,0,SUMIFS(tICICIAshu[Signed Amount],tICICIAshu[Display Scheme],$A22)+SUMIFS(tManiqAshu[Signed Amount],tManiqAshu[Display Scheme],$A22)+SUMIFS(tManiqHars[Signed Amount],tManiqHars[Display Scheme],$A22)+SUMIFS(tZerodhAshu[Signed Amount],tZerodhAshu[Display Scheme],$A22)+SUMIFS(tZerodhHars[Signed Amount],tZerodhHars[Display Scheme],$A22)) -> 99995.02 | D22: =IFERROR(IF(B22<0.01,0,C22/B22),0) -> 35.869101 | E22: =IFERROR(VLOOKUP($A22,tNAV[[Display Scheme]:[Latest NAV]],3,FALSE()),0) -> 36.7857 | F22: =B22*E22 -> 102550.29 | G22: =F22-(SUMIFS(tICICIAshu[Signed Amount],tICICIAshu[Display Scheme],$A22)+SUMIFS(tManiqAshu[Signed Amount],tManiqAshu[Display Scheme],$A22)+SUMIFS(tManiqHars[Signed Amount],tManiqHars[Display Scheme],$A22)+SUMIFS(tZerodhAshu[Signed Amount],tZerodhAshu[Display Scheme],$A22)+SUMIFS(tZerodhHars[Signed Amount],tZerodhHars[Display Scheme],$A22)) -> 2555.2716 | H22: =IF(B22<0.01,"Realized","Unrealized") -> Unrealized | I22: =IFERROR(G22/ABS(SUMIFS(tICICIAshu[Signed Amount],tICICIAshu[Display Scheme],$A22)+SUMIFS(tManiqAshu[Signed Amount],tManiqAshu[Display Scheme],$A22)+SUMIFS(tManiqHars[Signed Amount],tManiqHars[Display Scheme],$A22)+SUMIFS(tZerodhAshu[Signed Amount],tZerodhAshu[Display Scheme],$A22)+SUMIFS(tZerodhHars[Signed Amount],tZerodhHars[Display Scheme],$A22)),0) -> 0.025553989 | J22: =IF(B22<0.01,"Redeemed",IF(C22<=0,"Active",IF(G22>=0,"In Profit","In Loss"))) -> In Profit | K22: {=IFERROR(IF(F22<=0,"",XIRR(_xlfn.VSTACK(_xlfn._xlws.FILTER(-tAllCF[Signed Amount],tAllCF[Display Scheme]=$A22),F22),_xlfn.VSTACK(_xlfn._xlws.FILTER(tAllCF[Date],tAllCF[Display Scheme]=$A22),TODAY()))),"")} -> 0.064206973
... A41: Uti Focused Fund Growth | B41: =SUMIFS(tICICIAshu[Signed Unit],tICICIAshu[Display Scheme],$A41)+SUMIFS(tManiqAshu[Signed Unit],tManiqAshu[Display Scheme],$A41)+SUMIFS(tManiqHars[Signed Unit],tManiqHars[Display Scheme],$A41)+SUMIFS(tZerodhAshu[Signed Unit],tZerodhAshu[Display Scheme],$A41)+SUMIFS(tZerodhHars[Signed Unit],tZerodhHars[Display Scheme],$A41) -> 0 | C41: =IF(B41<0.01,0,SUMIFS(tICICIAshu[Signed Amount],tICICIAshu[Display Scheme],$A41)+SUMIFS(tManiqAshu[Signed Amount],tManiqAshu[Display Scheme],$A41)+SUMIFS(tManiqHars[Signed Amount],tManiqHars[Display Scheme],$A41)+SUMIFS(tZerodhAshu[Signed Amount],tZerodhAshu[Display Scheme],$A41)+SUMIFS(tZerodhHars[Signed Amount],tZerodhHars[Display Scheme],$A41)) -> 0 | D41: =IFERROR(IF(B41<0.01,0,C41/B41),0) -> 0 | E41: =IFERROR(VLOOKUP($A41,tNAV[[Display Scheme]:[Latest NAV]],3,FALSE()),0) -> 0 | F41: =B41*E41 -> 0 | G41: =F41-(SUMIFS(tICICIAshu[Signed Amount],tICICIAshu[Display Scheme],$A41)+SUMIFS(tManiqAshu[Signed Amount],tManiqAshu[Display Scheme],$A41)+SUMIFS(tManiqHars[Signed Amount],tManiqHars[Display Scheme],$A41)+SUMIFS(tZerodhAshu[Signed Amount],tZerodhAshu[Display Scheme],$A41)+SUMIFS(tZerodhHars[Signed Amount],tZerodhHars[Display Scheme],$A41)) -> 69316.53 | H41: =IF(B41<0.01,"Realized","Unrealized") -> Realized | I41: =IFERROR(G41/ABS(SUMIFS(tICICIAshu[Signed Amount],tICICIAshu[Display Scheme],$A41)+SUMIFS(tManiqAshu[Signed Amount],tManiqAshu[Display Scheme],$A41)+SUMIFS(tManiqHars[Signed Amount],tManiqHars[Display Scheme],$A41)+SUMIFS(tZerodhAshu[Signed Amount],tZerodhAshu[Display Scheme],$A41)+SUMIFS(tZerodhHars[Signed Amount],tZerodhHars[Display Scheme],$A41)),0) -> 1 | J41: =IF(B41<0.01,"Redeemed",IF(C41<=0,"Active",IF(G41>=0,"In Profit","In Loss"))) -> Redeemed | K41: {=IFERROR(IF(F41<=0,"",XIRR(_xlfn.VSTACK(_xlfn._xlws.FILTER(-tAllCF[Signed Amount],tAllCF[Display Scheme]=$A41),F41),_xlfn.VSTACK(_xlfn._xlws.FILTER(tAllCF[Date],tAllCF[Display Scheme]=$A41),TODAY()))),"")}
A42: TOTAL | C42: =SUBTOTAL(9,MFwise[Net Invested]) -> 4409837.1 | F42: =SUBTOTAL(9,MFwise[Current Value]) -> 6847516.3 | G42: =SUBTOTAL(9,MFwise[Gain/Loss]) -> 2437679.2 | I42: =IFERROR(G42/C42,0) -> 0.55278215
A45: Account-Wise Portfolio
A46: Account / Scheme | B46: Transactions | C46: Schemes | D46: Net Invested | E46: Current Value | F46: Gain/Loss | G46: % Gain | H46: P&L Type | I46: XIRR | J46: Status
A47: ICICI Direct - Ashutosh | B47: =COUNTA(tICICIAshu[Date]) -> 102 | C47: {=SUMPRODUCT((COUNTIF(tICICIAshu[Display Scheme],tICICIAshu[Display Scheme])>0)/COUNTIF(tICICIAshu[Display Scheme],tICICIAshu[Display Scheme]))} -> 10 | D47: =SUM(tICICIAshu[Signed Amount]) -> 1016099.4 | E47: {=SUMPRODUCT(SUMIFS(tICICIAshu[Signed Unit],tICICIAshu[Display Scheme],MFwise[Display Scheme])*MFwise[Latest NAV])} -> 2092589.2 | F47: =E47-D47 -> 1076489.7 | G47: =IFERROR(F47/D47,0) -> 1.0594335 | I47: {=IFERROR(IF(E47<=0,"",XIRR(_xlfn.VSTACK(-tICICIAshu[Signed Amount],E47),_xlfn.VSTACK(tICICIAshu[Date],TODAY()))),"")} -> 0.13134245 | J47: =IF(F47>=0,"In Profit","In Loss") -> In Profit
A48: Canara Robeco Large And Mid Cap Fund Growth | B48: =COUNTIFS(tICICIAshu[Display Scheme],"Canara Robeco Large And Mid Cap Fund Growth") -> 1 | D48: =MAX(0,SUMIFS(tICICIAshu[Signed Amount],tICICIAshu[Display Scheme],"Canara Robeco Large And Mid Cap Fund Growth")) -> 500000 | E48: =SUMIFS(tICICIAshu[Signed Unit],tICICIAshu[Display Scheme],"Canara Robeco Large And Mid Cap Fund Growth")*IFERROR(VLOOKUP("Canara Robeco Large And Mid Cap Fund Growth",tNAV[[Display Scheme]:[Latest NAV]],3,FALSE()),0) -> 886618.16 | F48: =E48-D48 -> 386618.16 | G48: =IF(E48<0.01,"",IFERROR(F48/D48,0)) -> 0.77323633 | H48: =IF(E48<0.01,"Realized","Unrealized") -> Unrealized | I48: {=IFERROR(IF(E48<=0,"",XIRR(_xlfn.VSTACK(_xlfn._xlws.FILTER(-tICICIAshu[Signed Amount],tICICIAshu[Display Scheme]="Canara Robeco Large And Mid Cap Fund Growth"),E48),_xlfn.VSTACK(_xlfn._xlws.FILTER(tICICIAshu[Date],tICICIAshu[Display Scheme]="Canara Robeco Large And Mid Cap Fund Growth"),TODAY()))),"")} -> 0.11992086 | J48: =IF(E48<0.01,"Redeemed",IF(F48>=0,"In Profit","In Loss")) -> In Profit
A49: Canara Robeco Large Cap Fund Regulargrowth | B49: =COUNTIFS(tICICIAshu[Display Scheme],"Canara Robeco Large Cap Fund Regulargrowth") -> 1 | D49: =MAX(0,SUMIFS(tICICIAshu[Signed Amount],tICICIAshu[Display Scheme],"Canara Robeco Large Cap Fund Regulargrowth")) -> 60000 | E49: =SUMIFS(tICICIAshu[Signed Unit],tICICIAshu[Display Scheme],"Canara Robeco Large Cap Fund Regulargrowth")*IFERROR(VLOOKUP("Canara Robeco Large Cap Fund Regulargrowth",tNAV[[Display Scheme]:[Latest NAV]],3,FALSE()),0) -> 86264.183 | F49: =E49-D49 -> 26264.183 | G49: =IF(E49<0.01,"",IFERROR(F49/D49,0)) -> 0.43773638 | H49: =IF(E49<0.01,"Realized","Unrealized") -> Unrealized | I49: {=IFERROR(IF(E49<=0,"",XIRR(_xlfn.VSTACK(_xlfn._xlws.FILTER(-tICICIAshu[Signed Amount],tICICIAshu[Display Scheme]="Canara Robeco Large Cap Fund Regulargrowth"),E49),_xlfn.VSTACK(_xlfn._xlws.FILTER(tICICIAshu[Date],tICICIAshu[Display Scheme]="Canara Robeco Large Cap Fund Regulargrowth"),TODAY()))),"")} -> 0.079373416 | J49: =IF(E49<0.01,"Redeemed",IF(F49>=0,"In Profit","In Loss")) -> In Profit
A50: Hdfc Mid Cap Fund - Growth Option | B50: =COUNTIFS(tICICIAshu[Display Scheme],"Hdfc Mid Cap Fund - Growth Option") -> 16 | D50: =MAX(0,SUMIFS(tICICIAshu[Signed Amount],tICICIAshu[Display Scheme],"Hdfc Mid Cap Fund - Growth Option")) -> 90000 | E50: =SUMIFS(tICICIAshu[Signed Unit],tICICIAshu[Display Scheme],"Hdfc Mid Cap Fund - Growth Option")*IFERROR(VLOOKUP("Hdfc Mid Cap Fund - Growth Option",tNAV[[Display Scheme]:[Latest NAV]],3,FALSE()),0) -> 423970.56 | F50: =E50-D50 -> 333970.56 | G50: =IF(E50<0.01,"",IFERROR(F50/D50,0)) -> 3.7107839 | H50: =IF(E50<0.01,"Realized","Unrealized") -> Unrealized | I50: {=IFERROR(IF(E50<=0,"",XIRR(_xlfn.VSTACK(_xlfn._xlws.FILTER(-tICICIAshu[Signed Amount],tICICIAshu[Display Scheme]="Hdfc Mid Cap Fund - Growth Option"),E50),_xlfn.VSTACK(_xlfn._xlws.FILTER(tICICIAshu[Date],tICICIAshu[Display Scheme]="Hdfc Mid Cap Fund - Growth Option"),TODAY()))),"")} -> 0.16650087 | J50: =IF(E50<0.01,"Redeemed",IF(F50>=0,"In Profit","In Loss")) -> In Profit
A51: Kotak Contra Fund - Growth | B51: =COUNTIFS(tICICIAshu[Display Scheme],"Kotak Contra Fund - Growth") -> 63 | D51: =MAX(0,SUMIFS(tICICIAshu[Signed Amount],tICICIAshu[Display Scheme],"Kotak Contra Fund - Growth")) -> 349000 | E51: =SUMIFS(tICICIAshu[Signed Unit],tICICIAshu[Display Scheme],"Kotak Contra Fund - Growth")*IFERROR(VLOOKUP("Kotak Contra Fund - Growth",tNAV[[Display Scheme]:[Latest NAV]],3,FALSE()),0) -> 499887.48 | F51: =E51-D51 -> 150887.48 | G51: =IF(E51<0.01,"",IFERROR(F51/D51,0)) -> 0.43234236 | H51: =IF(E51<0.01,"Realized","Unrealized") -> Unrealized | I51: {=IFERROR(IF(E51<=0,"",XIRR(_xlfn.VSTACK(_xlfn._xlws.FILTER(-tICICIAshu[Signed Amount],tICICIAshu[Display Scheme]="Kotak Contra Fund - Growth"),E51),_xlfn.VSTACK(_xlfn._xlws.FILTER(tICICIAshu[Date],tICICIAshu[Display Scheme]="Kotak Contra Fund - Growth"),TODAY()))),"")} -> 0.14008961 | J51: =IF(E51<0.01,"Redeemed",IF(F51>=0,"In Profit","In Loss")) -> In Profit
A52: Lnt Flexicap Fund Regular Growth Option | B52: =COUNTIFS(tICICIAshu[Display Scheme],"Lnt Flexicap Fund Regular Growth Option") -> 2 | D52: =MAX(0,SUMIFS(tICICIAshu[Signed Amount],tICICIAshu[Display Scheme],"Lnt Flexicap Fund Regular Growth Option")) -> 0 | E52: =SUMIFS(tICICIAshu[Signed Unit],tICICIAshu[Display Scheme],"Lnt Flexicap Fund Regular Growth Option")*IFERROR(VLOOKUP("Lnt Flexicap Fund Regular Growth Option",tNAV[[Display Scheme]:[Latest NAV]],3,FALSE()),0) -> 0 | F52: =E52-D52 -> 0 | G52: =IF(E52<0.01,"",IFERROR(F52/D52,0)) | H52: =IF(E52<0.01,"Realized","Unrealized") -> Realized | I52: {=IFERROR(IF(E52<=0,"",XIRR(_xlfn.VSTACK(_xlfn._xlws.FILTER(-tICICIAshu[Signed Amount],tICICIAshu[Display Scheme]="Lnt Flexicap Fund Regular Growth Option"),E52),_xlfn.VSTACK(_xlfn._xlws.FILTER(tICICIAshu[Date],tICICIAshu[Display Scheme]="Lnt Flexicap Fund Regular Growth Option"),TODAY()))),"")} | J52: =IF(E52<0.01,"Redeemed",IF(F52>=0,"In Profit","In Loss")) -> Redeemed
A53: Nippon India Elss Tax Saver Fund - Growth Plan | B53: =COUNTIFS(tICICIAshu[Display Scheme],"Nippon India Elss Tax Saver Fund - Growth Plan") -> 2 | D53: =MAX(0,SUMIFS(tICICIAshu[Signed Amount],tICICIAshu[Display Scheme],"Nippon India Elss Tax Saver Fund - Growth Plan")) -> 0 | E53: =SUMIFS(tICICIAshu[Signed Unit],tICICIAshu[Display Scheme],"Nippon India Elss Tax Saver Fund - Growth Plan")*IFERROR(VLOOKUP("Nippon India Elss Tax Saver Fund - Growth Plan",tNAV[[Display Scheme]:[Latest NAV]],3,FALSE()),0) -> 0 | F53: =E53-D53 -> 0 | G53: =IF(E53<0.01,"",IFERROR(F53/D53,0)) | H53: =IF(E53<0.01,"Realized","Unrealized") -> Realized | I53: {=IFERROR(IF(E53<=0,"",XIRR(_xlfn.VSTACK(_xlfn._xlws.FILTER(-tICICIAshu[Signed Amount],tICICIAshu[Display Scheme]="Nippon India Elss Tax Saver Fund - Growth Plan"),E53),_xlfn.VSTACK(_xlfn._xlws.FILTER(tICICIAshu[Date],tICICIAshu[Display Scheme]="Nippon India Elss Tax Saver Fund - Growth Plan"),TODAY()))),"")} | J53: =IF(E53<0.01,"Redeemed",IF(F53>=0,"In Profit","In Loss")) -> Redeemed
A54: Nippon India Equity Linked Savings Fund Series - I Growth | B54: =COUNTIFS(tICICIAshu[Display Scheme],"Nippon India Equity Linked Savings Fund Series - I Growth") -> 2 | D54: =MAX(0,SUMIFS(tICICIAshu[Signed Amount],tICICIAshu[Display Scheme],"Nippon India Equity Linked Savings Fund Series - I Growth")) -> 0 | E54: =SUMIFS(tICICIAshu[Signed Unit],tICICIAshu[Display Scheme],"Nippon India Equity Linked Savings Fund Series - I Growth")*IFERROR(VLOOKUP("Nippon India Equity Linked Savings Fund Series - I Growth",tNAV[[Display Scheme]:[Latest NAV]],3,FALSE()),0) -> 0 | F54: =E54-D54 -> 0 | G54: =IF(E54<0.01,"",IFERROR(F54/D54,0)) | H54: =IF(E54<0.01,"Realized","Unrealized") -> Realized | I54: {=IFERROR(IF(E54<=0,"",XIRR(_xlfn.VSTACK(_xlfn._xlws.FILTER(-tICICIAshu[Signed Amount],tICICIAshu[Display Scheme]="Nippon India Equity Linked Savings Fund Series - I Growth"),E54),_xlfn.VSTACK(_xlfn._xlws.FILTER(tICICIAshu[Date],tICICIAshu[Display Scheme]="Nippon India Equity Linked Savings Fund Series - I Growth"),TODAY()))),"")} | J54: =IF(E54<0.01,"Redeemed",IF(F54>=0,"In Profit","In Loss")) -> Redeemed
A55: Sbi Contra Fund Regular Idcw | B55: =COUNTIFS(tICICIAshu[Display Scheme],"Sbi Contra Fund Regular Idcw") -> 2 | D55: =MAX(0,SUMIFS(tICICIAshu[Signed Amount],tICICIAshu[Display Scheme],"Sbi Contra Fund Regular Idcw")) -> 0 | E55: =SUMIFS(tICICIAshu[Signed Unit],tICICIAshu[Display Scheme],"Sbi Contra Fund Regular Idcw")*IFERROR(VLOOKUP("Sbi Contra Fund Regular Idcw",tNAV[[Display Scheme]:[Latest NAV]],3,FALSE()),0) -> 0 | F55: =E55-D55 -> 0 | G55: =IF(E55<0.01,"",IFERROR(F55/D55,0)) | H55: =IF(E55<0.01,"Realized","Unrealized") -> Realized | I55: {=IFERROR(IF(E55<=0,"",XIRR(_xlfn.VSTACK(_xlfn._xlws.FILTER(-tICICIAshu[Signed Amount],tICICIAshu[Display Scheme]="Sbi Contra Fund Regular Idcw"),E55),_xlfn.VSTACK(_xlfn._xlws.FILTER(tICICIAshu[Date],tICICIAshu[Display Scheme]="Sbi Contra Fund Regular Idcw"),TODAY()))),"")} | J55: =IF(E55<0.01,"Redeemed",IF(F55>=0,"In Profit","In Loss")) -> Redeemed
A56: Sbi Elss Tax Saver Fund - Growth | B56: =COUNTIFS(tICICIAshu[Display Scheme],"Sbi Elss Tax Saver Fund - Growth") -> 1 | D56: =MAX(0,SUMIFS(tICICIAshu[Signed Amount],tICICIAshu[Display Scheme],"Sbi Elss Tax Saver Fund - Growth")) -> 5000 | E56: =SUMIFS(tICICIAshu[Signed Unit],tICICIAshu[Display Scheme],"Sbi Elss Tax Saver Fund - Growth")*IFERROR(VLOOKUP("Sbi Elss Tax Saver Fund - Growth",tNAV[[Display Scheme]:[Latest NAV]],3,FALSE()),0) -> 32675.35 | F56: =E56-D56 -> 27675.35 | G56: =IF(E56<0.01,"",IFERROR(F56/D56,0)) -> 5.5350699 | H56: =IF(E56<0.01,"Realized","Unrealized") -> Unrealized | I56: {=IFERROR(IF(E56<=0,"",XIRR(_xlfn.VSTACK(_xlfn._xlws.FILTER(-tICICIAshu[Signed Amount],tICICIAshu[Display Scheme]="Sbi Elss Tax Saver Fund - Growth"),E56),_xlfn.VSTACK(_xlfn._xlws.FILTER(tICICIAshu[Date],tICICIAshu[Display Scheme]="Sbi Elss Tax Saver Fund - Growth"),TODAY()))),"")} -> 0.10653883 | J56: =IF(E56<0.01,"Redeemed",IF(F56>=0,"In Profit","In Loss")) -> In Profit
A57: Sbi Flexicap Fund - Growth | B57: =COUNTIFS(tICICIAshu[Display Scheme],"Sbi Flexicap Fund - Growth") -> 12 | D57: =MAX(0,SUMIFS(tICICIAshu[Signed Amount],tICICIAshu[Display Scheme],"Sbi Flexicap Fund - Growth")) -> 60000 | E57: =SUMIFS(tICICIAshu[Signed Unit],tICICIAshu[Display Scheme],"Sbi Flexicap Fund - Growth")*IFERROR(VLOOKUP("Sbi Flexicap Fund - Growth",tNAV[[Display Scheme]:[Latest NAV]],3,FALSE()),0) -> 163173.44 | F57: =E57-D57 -> 103173.44 | G57: =IF(E57<0.01,"",IFERROR(F57/D57,0)) -> 1.7195574 | H57: =IF(E57<0.01,"Realized","Unrealized") -> Unrealized | I57: {=IFERROR(IF(E57<=0,"",XIRR(_xlfn.VSTACK(_xlfn._xlws.FILTER(-tICICIAshu[Signed Amount],tICICIAshu[Display Scheme]="Sbi Flexicap Fund - Growth"),E57),_xlfn.VSTACK(_xlfn._xlws.FILTER(tICICIAshu[Date],tICICIAshu[Display Scheme]="Sbi Flexicap Fund - Growth"),TODAY()))),"")} -> 0.11332076 | J57: =IF(E57<0.01,"Redeemed",IF(F57>=0,"In Profit","In Loss")) -> In Profit
A58: Maniqmala - Ashutosh | B58: =COUNTA(tManiqAshu[Date]) -> 191 | C58: {=SUMPRODUCT((COUNTIF(tManiqAshu[Display Scheme],tManiqAshu[Display Scheme])>0)/COUNTIF(tManiqAshu[Display Scheme],tManiqAshu[Display Scheme]))} -> 4 | D58: =SUM(tManiqAshu[Signed Amount]) -> 943453.46 | E58: {=SUMPRODUCT(SUMIFS(tManiqAshu[Signed Unit],tManiqAshu[Display Scheme],MFwise[Display Scheme])*MFwise[Latest NAV])} -> 1392549.7 | F58: =E58-D58 -> 449096.19 | G58: =IFERROR(F58/D58,0) -> 0.47601309 | I58: {=IFERROR(IF(E58<=0,"",XIRR(_xlfn.VSTACK(-tManiqAshu[Signed Amount],E58),_xlfn.VSTACK(tManiqAshu[Date],TODAY()))),"")} -> 0.10531805 | J58: =IF(F58>=0,"In Profit","In Loss") -> In Profit
A59: Aditya Birla Sun Life Banking And Financial Services Fund Growth | B59: =COUNTIFS(tManiqAshu[Display Scheme],"Aditya Birla Sun Life Banking And Financial Services Fund Growth") -> 64 | D59: =MAX(0,SUMIFS(tManiqAshu[Signed Amount],tManiqAshu[Display Scheme],"Aditya Birla Sun Life Banking And Financial Services Fund Growth")) -> 159992.32 | E59: =SUMIFS(tManiqAshu[Signed Unit],tManiqAshu[Display Scheme],"Aditya Birla Sun Life Banking And Financial Services Fund Growth")*IFERROR(VLOOKUP("Aditya Birla Sun Life Banking And Financial Services Fund Growth",tNAV[[Display Scheme]:[Latest NAV]],3,FALSE()),0) -> 221027.78 | F59: =E59-D59 -> 61035.455 | G59: =IF(E59<0.01,"",IFERROR(F59/D59,0)) -> 0.38148991 | H59: =IF(E59<0.01,"Realized","Unrealized") -> Unrealized | I59: {=IFERROR(IF(E59<=0,"",XIRR(_xlfn.VSTACK(_xlfn._xlws.FILTER(-tManiqAshu[Signed Amount],tManiqAshu[Display Scheme]="Aditya Birla Sun Life Banking And Financial Services Fund Growth"),E59),_xlfn.VSTACK(_xlfn._xlws.FILTER(tManiqAshu[Date],tManiqAshu[Display Scheme]="Aditya Birla Sun Life Banking And Financial Services Fund Growth"),TODAY()))),"")} -> 0.12381911 | J59: =IF(E59<0.01,"Redeemed",IF(F59>=0,"In Profit","In Loss")) -> In Profit
A60: Mahindra Manulife Flexi Cap Fund Growth | B60: =COUNTIFS(tManiqAshu[Display Scheme],"Mahindra Manulife Flexi Cap Fund Growth") -> 1 | D60: =MAX(0,SUMIFS(tManiqAshu[Signed Amount],tManiqAshu[Display Scheme],"Mahindra Manulife Flexi Cap Fund Growth")) -> 499975 | E60: =SUMIFS(tManiqAshu[Signed Unit],tManiqAshu[Display Scheme],"Mahindra Manulife Flexi Cap Fund Growth")*IFERROR(VLOOKUP("Mahindra Manulife Flexi Cap Fund Growth",tNAV[[Display Scheme]:[Latest NAV]],3,FALSE()),0) -> 779663.3 | F60: =E60-D60 -> 279688.3 | G60: =IF(E60<0.01,"",IFERROR(F60/D60,0)) -> 0.55940457 | H60: =IF(E60<0.01,"Realized","Unrealized") -> Unrealized | I60: {=IFERROR(IF(E60<=0,"",XIRR(_xlfn.VSTACK(_xlfn._xlws.FILTER(-tManiqAshu[Signed Amount],tManiqAshu[Display Scheme]="Mahindra Manulife Flexi Cap Fund Growth"),E60),_xlfn.VSTACK(_xlfn._xlws.FILTER(tManiqAshu[Date],tManiqAshu[Display Scheme]="Mahindra Manulife Flexi Cap Fund Growth"),TODAY()))),"")} -> 0.096809071 | J60: =IF(E60<0.01,"Redeemed",IF(F60>=0,"In Profit","In Loss")) -> In Profit
...

Sheet NAV Reference
A1: NAV Reference — Latest NAV per Display Scheme
A2: NAVs sourced from MoneyControl portfolio exports where available; otherwise the most recent transaction NAV is used. Edit values here to refresh the dashboard.
A4: Display Scheme | B4: Scheme Key | C4: Latest NAV | D4: NAV Source | E4: Notes | F4: Scheme Code | G4: Remarks
A5: Aditya Birla Sun Life Banking And Financial Services Fund Growth | B5: adityabirlasunlifeba | C5: =IF(F5="",0,IFERROR(VLOOKUP(F5,NAVAll!$A:$E,5,FALSE),0)) -> 63.59 | D5: =IF(F5="","Redeemed",IF(ISNUMBER(VLOOKUP(F5,NAVAll!$A:$E,5,FALSE)),"NAVAll","Last txn NAV")) -> NAVAll | F5: 125595
A6: Aditya Birla Sun Life Value Fund Growth | B6: adityabirlasunlifeva | C6: =IF(F6="",0,IFERROR(VLOOKUP(F6,NAVAll!$A:$E,5,FALSE),0)) -> 133.0035 | D6: =IF(F6="","Redeemed",IF(ISNUMBER(VLOOKUP(F6,NAVAll!$A:$E,5,FALSE)),"NAVAll","Last txn NAV")) -> NAVAll | F6: 108167
A7: Canara Robeco Large And Mid Cap Fund Growth | B7: canararobecolargemid | C7: =IF(F7="",0,IFERROR(VLOOKUP(F7,NAVAll!$A:$E,5,FALSE),0)) -> 250.89 | D7: =IF(F7="","Redeemed",IF(ISNUMBER(VLOOKUP(F7,NAVAll!$A:$E,5,FALSE)),"NAVAll","Last txn NAV")) -> NAVAll | F7: 102920
A8: Canara Robeco Large Cap Fund Regulargrowth | B8: canararobecolargecap | C8: =IF(F8="",0,IFERROR(VLOOKUP(F8,NAVAll!$A:$E,5,FALSE),0)) -> 61.15 | D8: =IF(F8="","Redeemed",IF(ISNUMBER(VLOOKUP(F8,NAVAll!$A:$E,5,FALSE)),"NAVAll","Last txn NAV")) -> NAVAll | F8: 113221
A9: Hdfc Flexicap Fund Direct Growth Option | B9: hdfcflexicapfund | C9: =IF(F9="",0,IFERROR(VLOOKUP(F9,NAVAll!$A:$E,5,FALSE),0)) -> 2215.087 | D9: =IF(F9="","Redeemed",IF(ISNUMBER(VLOOKUP(F9,NAVAll!$A:$E,5,FALSE)),"NAVAll","Last txn NAV")) -> NAVAll | F9: 118955
A10: Hdfc Gold Etf Fund Of Fund Direct Growth Option | B10: hdfcgoldetffundoffun | C10: =IF(F10="",0,IFERROR(VLOOKUP(F10,NAVAll!$A:$E,5,FALSE),0)) -> 43.279 | D10: =IF(F10="","Redeemed",IF(ISNUMBER(VLOOKUP(F10,NAVAll!$A:$E,5,FALSE)),"NAVAll","Last txn NAV")) -> NAVAll | F10: 119132
A11: Hdfc Mid Cap Fund - Growth Option | B11: hdfcmidcapfund | C11: =IF(F11="",0,IFERROR(VLOOKUP(F11,NAVAll!$A:$E,5,FALSE),0)) -> 204.864 | D11: =IF(F11="","Redeemed",IF(ISNUMBER(VLOOKUP(F11,NAVAll!$A:$E,5,FALSE)),"NAVAll","Last txn NAV")) -> NAVAll | F11: 105758
A12: Hdfc Silver Etf Fund Of Fund Direct Growth | B12: hdfcsilveretffundoff | C12: =IF(F12="",0,IFERROR(VLOOKUP(F12,NAVAll!$A:$E,5,FALSE),0)) -> 35.6537 | D12: =IF(F12="","Redeemed",IF(ISNUMBER(VLOOKUP(F12,NAVAll!$A:$E,5,FALSE)),"NAVAll","Last txn NAV")) -> NAVAll | F12: 150737
A13: Icici Prudential Balanced Advantage Fund Direct Growth | B13: iciciprudentialbalan | C13: =IF(F13="",0,IFERROR(VLOOKUP(F13,NAVAll!$A:$E,5,FALSE),0)) -> 86.86 | D13: =IF(F13="","Redeemed",IF(ISNUMBER(VLOOKUP(F13,NAVAll!$A:$E,5,FALSE)),"NAVAll","Last txn NAV")) -> NAVAll | F13: 120377
A14: Icici Prudential Focused Equity Fund Growth | B14: iciciprudentialfocus | C14: =IF(F14="",0,IFERROR(VLOOKUP(F14,NAVAll!$A:$E,5,FALSE),0)) -> 93.49 | D14: =IF(F14="","Redeemed",IF(ISNUMBER(VLOOKUP(F14,NAVAll!$A:$E,5,FALSE)),"NAVAll","Last txn NAV")) -> NAVAll | F14: 111957
A15: Icici Prudential Value Fund Growth | B15: iciciprudentialvalue | C15: =IF(F15="",0,IFERROR(VLOOKUP(F15,NAVAll!$A:$E,5,FALSE),0)) -> 462.41 | D15: =IF(F15="","Redeemed",IF(ISNUMBER(VLOOKUP(F15,NAVAll!$A:$E,5,FALSE)),"NAVAll","Last txn NAV")) -> NAVAll | F15: 102594
A16: Invesco India Arbitrage Fund - Direct Plan Growth | B16: invescoindiaarbitrag | C16: =IF(F16="",0,IFERROR(VLOOKUP(F16,NAVAll!$A:$E,5,FALSE),0)) -> 36.7857 | D16: =IF(F16="","Redeemed",IF(ISNUMBER(VLOOKUP(F16,NAVAll!$A:$E,5,FALSE)),"NAVAll","Last txn NAV")) -> NAVAll | F16: 120401
A17: Invesco India Contra Fund - Direct Plan | B17: invescoindiacontrafu | C17: =IF(F17="",0,IFERROR(VLOOKUP(F17,NAVAll!$A:$E,5,FALSE),0)) -> 157.4 | D17: =IF(F17="","Redeemed",IF(ISNUMBER(VLOOKUP(F17,NAVAll!$A:$E,5,FALSE)),"NAVAll","Last txn NAV")) -> NAVAll | F17: 120348
A18: Invesco India Multicap Fund Growth | B18: invescoindiamulticap | C18: =IF(F18="",0,IFERROR(VLOOKUP(F18,NAVAll!$A:$E,5,FALSE),0)) -> 0 | D18: =IF(F18="","Redeemed",IF(ISNUMBER(VLOOKUP(F18,NAVAll!$A:$E,5,FALSE)),"NAVAll","Last txn NAV")) -> Redeemed | G18: Already redeemed
A19: Kotak Contra Fund - Growth | B19: kotakcontrafund | C19: =IF(F19="",0,IFERROR(VLOOKUP(F19,NAVAll!$A:$E,5,FALSE),0)) -> 151.745 | D19: =IF(F19="","Redeemed",IF(ISNUMBER(VLOOKUP(F19,NAVAll!$A:$E,5,FALSE)),"NAVAll","Last txn NAV")) -> NAVAll | F19: 103040
A20: Kotak Multicap Fund Growth | B20: kotakmulticapfund | C20: =IF(F20="",0,IFERROR(VLOOKUP(F20,NAVAll!$A:$E,5,FALSE),0)) -> 19.991 | D20: =IF(F20="","Redeemed",IF(ISNUMBER(VLOOKUP(F20,NAVAll!$A:$E,5,FALSE)),"NAVAll","Last txn NAV")) -> NAVAll | F20: 149182
A21: Lnt Flexicap Fund Regular Growth Option | B21: lntflexicapfund | C21: =IF(F21="",0,IFERROR(VLOOKUP(F21,NAVAll!$A:$E,5,FALSE),0)) -> 0 | D21: =IF(F21="","Redeemed",IF(ISNUMBER(VLOOKUP(F21,NAVAll!$A:$E,5,FALSE)),"NAVAll","Last txn NAV")) -> Redeemed | G21: Already redeemed
A22: Mahindra Manulife Flexi Cap Fund Growth | B22: mahindramanulifeflex | C22: =IF(F22="",0,IFERROR(VLOOKUP(F22,NAVAll!$A:$E,5,FALSE),0)) -> 15.7556 | D22: =IF(F22="","Redeemed",IF(ISNUMBER(VLOOKUP(F22,NAVAll!$A:$E,5,FALSE)),"NAVAll","Last txn NAV")) -> NAVAll | F22: 149101
A23: Mahindra Manulife Focused Fund Growth | B23: mahindramanulifefocu | C23: =IF(F23="",0,IFERROR(VLOOKUP(F23,NAVAll!$A:$E,5,FALSE),0)) -> 26.9523 | D23: =IF(F23="","Redeemed",IF(ISNUMBER(VLOOKUP(F23,NAVAll!$A:$E,5,FALSE)),"NAVAll","Last txn NAV")) -> NAVAll | F23: 148571
A24: Mahindra Manulife Large And Mid Cap Fund Growth | B24: mahindramanulifelarg | C24: =IF(F24="",0,IFERROR(VLOOKUP(F24,NAVAll!$A:$E,5,FALSE),0)) -> 26.9111 | D24: =IF(F24="","Redeemed",IF(ISNUMBER(VLOOKUP(F24,NAVAll!$A:$E,5,FALSE)),"NAVAll","Last txn NAV")) -> NAVAll | F24: 147843
A25: Mahindra Manulife Mid Cap Fund Growth | B25: mahindramanulifemidc | C25: =IF(F25="",0,IFERROR(VLOOKUP(F25,NAVAll!$A:$E,5,FALSE),0)) -> 36.2885 | D25: =IF(F25="","Redeemed",IF(ISNUMBER(VLOOKUP(F25,NAVAll!$A:$E,5,FALSE)),"NAVAll","Last txn NAV")) -> NAVAll | F25: 142109
A26: Mirae Asset Large And Mid Cap Fund Growth | B26: miraeassetlargemidca | C26: =IF(F26="",0,IFERROR(VLOOKUP(F26,NAVAll!$A:$E,5,FALSE),0)) -> 154.526 | D26: =IF(F26="","Redeemed",IF(ISNUMBER(VLOOKUP(F26,NAVAll!$A:$E,5,FALSE)),"NAVAll","Last txn NAV")) -> NAVAll | F26: 112932
A27: Nippon India Elss Tax Saver Fund - Growth Plan | B27: nipponindiaelsstaxsa | C27: =IF(F27="",0,IFERROR(VLOOKUP(F27,NAVAll!$A:$E,5,FALSE),0)) -> 131.2407 | D27: =IF(F27="","Redeemed",IF(ISNUMBER(VLOOKUP(F27,NAVAll!$A:$E,5,FALSE)),"NAVAll","Last txn NAV")) -> NAVAll | F27: 103196 | G27: Already redeemed
A28: Nippon India Equity Linked Savings Fund Series - I Growth | B28: nipponindiaequitylin | C28: =IF(F28="",0,IFERROR(VLOOKUP(F28,NAVAll!$A:$E,5,FALSE),0)) -> 0 | D28: =IF(F28="","Redeemed",IF(ISNUMBER(VLOOKUP(F28,NAVAll!$A:$E,5,FALSE)),"NAVAll","Last txn NAV")) -> Redeemed | G28: Already redeemed
A29: Principal Emerging Bluechip Fund Growth | B29: principalemergingblu | C29: =IF(F29="",0,IFERROR(VLOOKUP(F29,NAVAll!$A:$E,5,FALSE),0)) -> 0 | D29: =IF(F29="","Redeemed",IF(ISNUMBER(VLOOKUP(F29,NAVAll!$A:$E,5,FALSE)),"NAVAll","Last txn NAV")) -> Redeemed | G29: Already redeemed
A30: Sbi Contra Fund Regular Idcw | B30: sbicontrafund | C30: =IF(F30="",0,IFERROR(VLOOKUP(F30,NAVAll!$A:$E,5,FALSE),0)) -> 0 | D30: =IF(F30="","Redeemed",IF(ISNUMBER(VLOOKUP(F30,NAVAll!$A:$E,5,FALSE)),"NAVAll","Last txn NAV")) -> Redeemed | G30: Already redeemed
A31: Sbi Elss Tax Saver Fund - Growth | B31: sbielsstaxsaverfund | C31: =IF(F31="",0,IFERROR(VLOOKUP(F31,NAVAll!$A:$E,5,FALSE),0)) -> 436.6786 | D31: =IF(F31="","Redeemed",IF(ISNUMBER(VLOOKUP(F31,NAVAll!$A:$E,5,FALSE)),"NAVAll","Last txn NAV")) -> NAVAll | F31: 105628
A32: Sbi Flexicap Fund - Growth | B32: sbiflexicapfund | C32: =IF(F32="",0,IFERROR(VLOOKUP(F32,NAVAll!$A:$E,5,FALSE),0)) -> 106.9365 | D32: =IF(F32="","Redeemed",IF(ISNUMBER(VLOOKUP(F32,NAVAll!$A:$E,5,FALSE)),"NAVAll","Last txn NAV")) -> NAVAll | F32: 103215
A33: Sbi Small Cap Fund Growth | B33: sbismallcapfund | C33: =IF(F33="",0,IFERROR(VLOOKUP(F33,NAVAll!$A:$E,5,FALSE),0)) -> 176.8409 | D33: =IF(F33="","Redeemed",IF(ISNUMBER(VLOOKUP(F33,NAVAll!$A:$E,5,FALSE)),"NAVAll","Last txn NAV")) -> NAVAll | F33: 125494
A34: Sundaram Large And Mid Cap Fund Growth | B34: sundaramlargemidcapf | C34: =IF(F34="",0,IFERROR(VLOOKUP(F34,NAVAll!$A:$E,5,FALSE),0)) -> 0 | D34: =IF(F34="","Redeemed",IF(ISNUMBER(VLOOKUP(F34,NAVAll!$A:$E,5,FALSE)),"NAVAll","Last txn NAV")) -> Redeemed | G34: Already redeemed
A35: Uti Focused Fund Growth | B35: utifocusedfund | C35: =IF(F35="",0,IFERROR(VLOOKUP(F35,NAVAll!$A:$E,5,FALSE),0)) -> 0 | D35: =IF(F35="","Redeemed",IF(ISNUMBER(VLOOKUP(F35,NAVAll!$A:$E,5,FALSE)),"NAVAll","Last txn NAV")) -> Redeemed | G35: Already redeemed

Sheet Scheme Map
A1: Scheme Map — Raw Platform Scheme → Canonical Display Name
A2: Each platform names schemes differently. The Display column is what the Dashboard groups by. Edit Display values here to merge two raw schemes under one canonical name.
A4: Scheme Name (raw) | B4: Scheme Key | C4: Display Scheme
A5: Aditya Birla Sun Life Banking and Financial Services Fund Growth | B5: adityabirlasunlifeba | C5: Aditya Birla Sun Life Banking And Financial Services Fund Growth
A6: Aditya Birla Sun Life Value Fund Growth | B6: adityabirlasunlifeva | C6: Aditya Birla Sun Life Value Fund Growth
A7: Canara Robeco Large And Mid Cap Fund Regular -Growth | B7: canararobecolargemid | C7: Canara Robeco Large And Mid Cap Fund Growth
A8: Canara Robeco Large and Mid Cap Fund Growth | B8: canararobecolargemid | C8: Canara Robeco Large And Mid Cap Fund Growth
A9: Canara Robeco Large Cap Fund Regulargrowth | B9: canararobecolargecap | C9: Canara Robeco Large Cap Fund Regulargrowth
A10: Hdfc Flexicap Fund - Direct Plan - Growth Option | B10: hdfcflexicapfund | C10: Hdfc Flexicap Fund Direct Growth Option
A11: Hdfc Gold Etf Fund Of Fund - Direct Plan - Growth Option | B11: hdfcgoldetffundoffun | C11: Hdfc Gold Etf Fund Of Fund Direct Growth Option
A12: HDFC Mid Cap Fund - Growth Option | B12: hdfcmidcapfund | C12: Hdfc Mid Cap Fund - Growth Option
A13: Hdfc Silver Etf Fund Of Fund Direct Growth | B13: hdfcsilveretffundoff | C13: Hdfc Silver Etf Fund Of Fund Direct Growth
A14: Icici Prudential Balanced Advantage Fund - Direct Plan - Growth | B14: iciciprudentialbalan | C14: Icici Prudential Balanced Advantage Fund Direct Growth
A15: ICICI Prudential Focused Equity Fund Growth | B15: iciciprudentialfocus | C15: Icici Prudential Focused Equity Fund Growth
... A37: UTI Focused Fund Growth | B37: utifocusedfund | C37: Uti Focused Fund Growth

Sheet Txn-ICICI-Ashu
A1: Transactions — ICICI Direct - Ashutosh
A2: 100 transactions • Add or delete rows freely — the Dashboard auto-recomputes via the Excel table named 'tICICIAshu'.
A4: Date | B4: Transaction ID | C4: Transaction Type | D4: Fund Name | E4: Scheme Name | F4: Display Scheme | G4: Folio No | H4: Last recorded NAV | I4: Amount | J4: Unit | K4: Signed Unit | L4: Signed Amount | M4: Status
A5: 46192 | B5: 220886957 | C5: Purchase | D5: Kotak Mahindra Mutual Fund | E5: Kotak Contra Fund - Growth | F5: Kotak Contra Fund - Growth | G5: 8338255 | H5: 152.096 | I5: 6000 | J5: 39.447 | K5: 39.447 | L5: =IF(EXACT(tICICIAshu[[#This Row],[Transaction Type]],"Initial Purchase Pre-Rejection"),0,IF(OR(EXACT(tICICIAshu[[#This Row],[Transaction Type]],"Redemption"),EXACT(tICICIAshu[[#This Row],[Transaction Type]],"Redeem"),EXACT(tICICIAshu[[#This Row],[Transaction Type]],"Switch Out"),EXACT(tICICIAshu[[#This Row],[Transaction Type]],"sell"),EXACT(tICICIAshu[[#This Row],[Transaction Type]],"Sell")),-tICICIAshu[[#This Row],[Amount]],tICICIAshu[[#This Row],[Amount]])) -> 6000 | M5: Executed
A6: 46161 | B6: 220886958 | C6: Purchase | D6: Kotak Mahindra Mutual Fund | E6: Kotak Contra Fund - Growth | F6: Kotak Contra Fund - Growth | G6: 8338255 | H6: 146.33 | I6: 6000 | J6: 41.001 | K6: 41.001 | L6: =IF(EXACT(tICICIAshu[[#This Row],[Transaction Type]],"Initial Purchase Pre-Rejection"),0,IF(OR(EXACT(tICICIAshu[[#This Row],[Transaction Type]],"Redemption"),EXACT(tICICIAshu[[#This Row],[Transaction Type]],"Redeem"),EXACT(tICICIAshu[[#This Row],[Transaction Type]],"Switch Out"),EXACT(tICICIAshu[[#This Row],[Transaction Type]],"sell"),EXACT(tICICIAshu[[#This Row],[Transaction Type]],"Sell")),-tICICIAshu[[#This Row],[Amount]],tICICIAshu[[#This Row],[Amount]])) -> 6000 | M6: Executed
A7: 46131 | B7: 220886959 | C7: Purchase | D7: Kotak Mahindra Mutual Fund | E7: Kotak Contra Fund - Growth | F7: Kotak Contra Fund - Growth | G7: 8338255 | H7: 149.797 | I7: 6000 | J7: 40.052 | K7: =IF(OR(EXACT(C7,"Redemption"),EXACT(C7,"Redeem"),EXACT(C7,"Switch Out"),EXACT(C7,"sell"),EXACT(C7,"Sell")),-J7,J7) -> 40.052 | L7: =IF(EXACT(tICICIAshu[[#This Row],[Transaction Type]],"Initial Purchase Pre-Rejection"),0,IF(OR(EXACT(tICICIAshu[[#This Row],[Transaction Type]],"Redemption"),EXACT(tICICIAshu[[#This Row],[Transaction Type]],"Redeem"),EXACT(tICICIAshu[[#This Row],[Transaction Type]],"Switch Out"),EXACT(tICICIAshu[[#This Row],[Transaction Type]],"sell"),EXACT(tICICIAshu[[#This Row],[Transaction Type]],"Sell")),-tICICIAshu[[#This Row],[Amount]],tICICIAshu[[#This Row],[Amount]])) -> 6000 | M7: Executed
A8: 46100 | B8: 218814304 | C8: Purchase | D8: Kotak Mahindra Mutual Fund | E8: Kotak Contra Fund - Growth | F8: Kotak Contra Fund - Growth | G8: 8338255 | H8: 140.882 | I8: 6000 | J8: 42.587 | K8: =IF(OR(EXACT(C8,"Redemption"),EXACT(C8,"Redeem"),EXACT(C8,"Switch Out"),EXACT(C8,"sell"),EXACT(C8,"Sell")),-J8,J8) -> 42.587 | L8: =IF(EXACT(tICICIAshu[[#This Row],[Transaction Type]],"Initial Purchase Pre-Rejection"),0,IF(OR(EXACT(tICICIAshu[[#This Row],[Transaction Type]],"Redemption"),EXACT(tICICIAshu[[#This Row],[Transaction Type]],"Redeem"),EXACT(tICICIAshu[[#This Row],[Transaction Type]],"Switch Out"),EXACT(tICICIAshu[[#This Row],[Transaction Type]],"sell"),EXACT(tICICIAshu[[#This Row],[Transaction Type]],"Sell")),-tICICIAshu[[#This Row],[Amount]],tICICIAshu[[#This Row],[Amount]])) -> 6000 | M8: Executed
A9: 46072 | B9: 216658609 | C9: Purchase | D9: Kotak Mahindra Mutual Fund | E9: Kotak Contra Fund - Growth | F9: Kotak Contra Fund - Growth | G9: 8338255 | H9: 155.095 | I9: 6000 | J9: 38.684 | K9: =IF(OR(EXACT(C9,"Redemption"),EXACT(C9,"Redeem"),EXACT(C9,"Switch Out"),EXACT(C9,"sell"),EXACT(C9,"Sell")),-J9,J9) -> 38.684 | L9: =IF(EXACT(tICICIAshu[[#This Row],[Transaction Type]],"Initial Purchase Pre-Rejection"),0,IF(OR(EXACT(tICICIAshu[[#This Row],[Transaction Type]],"Redemption"),EXACT(tICICIAshu[[#This Row],[Transaction Type]],"Redeem"),EXACT(tICICIAshu[[#This Row],[Transaction Type]],"Switch Out"),EXACT(tICICIAshu[[#This Row],[Transaction Type]],"sell"),EXACT(tICICIAshu[[#This Row],[Transaction Type]],"Sell")),-tICICIAshu[[#This Row],[Amount]],tICICIAshu[[#This Row],[Amount]])) -> 6000 | M9: Executed
A10: 46041 | B10: 214503559 | C10: Purchase | D10: Kotak Mahindra Mutual Fund | E10: Kotak Contra Fund - Growth | F10: Kotak Contra Fund - Growth | G10: 8338255 | H10: 154.768 | I10: 5500 | J10: 35.535 | K10: =IF(OR(EXACT(C10,"Redemption"),EXACT(C10,"Redeem"),EXACT(C10,"Switch Out"),EXACT(C10,"sell"),EXACT(C10,"Sell")),-J10,J10) -> 35.535 | L10: =IF(EXACT(tICICIAshu[[#This Row],[Transaction Type]],"Initial Purchase Pre-Rejection"),0,IF(OR(EXACT(tICICIAshu[[#This Row],[Transaction Type]],"Redemption"),EXACT(tICICIAshu[[#This Row],[Transaction Type]],"Redeem"),EXACT(tICICIAshu[[#This Row],[Transaction Type]],"Switch Out"),EXACT(tICICIAshu[[#This Row],[Transaction Type]],"sell"),EXACT(tICICIAshu[[#This Row],[Transaction Type]],"Sell")),-tICICIAshu[[#This Row],[Amount]],tICICIAshu[[#This Row],[Amount]])) -> 5500 | M10: Executed
A11: 46010 | B11: 212399210 | C11: Purchase | D11: Kotak Mahindra Mutual Fund | E11: Kotak Contra Fund - Growth | F11: Kotak Contra Fund - Growth | G11: 8338255 | H11: 155.174 | I11: 5500 | J11: 35.442 | K11: =IF(OR(EXACT(C11,"Redemption"),EXACT(C11,"Redeem"),EXACT(C11,"Switch Out"),EXACT(C11,"sell"),EXACT(C11,"Sell")),-J11,J11) -> 35.442 | L11: =IF(EXACT(tICICIAshu[[#This Row],[Transaction Type]],"Initial Purchase Pre-Rejection"),0,IF(OR(EXACT(tICICIAshu[[#This Row],[Transaction Type]],"Redemption"),EXACT(tICICIAshu[[#This Row],[Transaction Type]],"Redeem"),EXACT(tICICIAshu[[#This Row],[Transaction Type]],"Switch Out"),EXACT(tICICIAshu[[#This Row],[Transaction Type]],"sell"),EXACT(tICICIAshu[[#This Row],[Transaction Type]],"Sell")),-tICICIAshu[[#This Row],[Amount]],tICICIAshu[[#This Row],[Amount]])) -> 5500 | M11: Executed
